2024-09-23 06:45:21,178 DEBUG: Logging configured [in /home/dietpi/nlpservice/app/main.py:38]
2024-09-23 06:45:21,178 DEBUG: Logging configured [in /home/dietpi/nlpservice/app/main.py:38]
2024-09-23 06:45:21,178 DEBUG: Logging configured [in /home/dietpi/nlpservice/app/main.py:38]
2024-09-23 06:45:21,178 DEBUG: Logging configured [in /home/dietpi/nlpservice/app/main.py:38]
2024-09-23 06:45:21,178 INFO: NLP Service startup [in /home/dietpi/nlpservice/app/main.py:39]
2024-09-23 06:45:21,178 INFO: NLP Service startup [in /home/dietpi/nlpservice/app/main.py:39]
2024-09-23 06:45:21,178 INFO: NLP Service startup [in /home/dietpi/nlpservice/app/main.py:39]
2024-09-23 06:45:21,178 INFO: NLP Service startup [in /home/dietpi/nlpservice/app/main.py:39]
2024-09-23 06:45:21,179 INFO: NLP Service startup [in /home/dietpi/nlpservice/app/main.py:60]
2024-09-23 06:45:21,179 INFO: NLP Service startup [in /home/dietpi/nlpservice/app/main.py:60]
2024-09-23 06:45:21,179 INFO: NLP Service startup [in /home/dietpi/nlpservice/app/main.py:60]
2024-09-23 06:45:21,179 INFO: NLP Service startup [in /home/dietpi/nlpservice/app/main.py:60]
2024-09-23 06:45:21,179 INFO: NLP Service startup [in /home/dietpi/nlpservice/app/main.py:60]
2024-09-23 06:45:21,179 INFO: NLP Service startup [in /home/dietpi/nlpservice/app/main.py:60]
2024-09-23 06:45:28,858 ERROR: Unhandled exception: name 'current_app' is not defined [in /home/dietpi/nlpservice/app/main.py:92]
2024-09-23 06:45:28,858 ERROR: Unhandled exception: name 'current_app' is not defined [in /home/dietpi/nlpservice/app/main.py:92]
2024-09-23 06:45:28,858 ERROR: Unhandled exception: name 'current_app' is not defined [in /home/dietpi/nlpservice/app/main.py:92]
2024-09-23 06:46:03,334 DEBUG: Logging configured [in /home/dietpi/nlpservice/app/main.py:38]
2024-09-23 06:46:03,334 DEBUG: Logging configured [in /home/dietpi/nlpservice/app/main.py:38]
2024-09-23 06:46:03,334 DEBUG: Logging configured [in /home/dietpi/nlpservice/app/main.py:38]
2024-09-23 06:46:03,334 DEBUG: Logging configured [in /home/dietpi/nlpservice/app/main.py:38]
2024-09-23 06:46:03,334 INFO: NLP Service startup [in /home/dietpi/nlpservice/app/main.py:39]
2024-09-23 06:46:03,334 INFO: NLP Service startup [in /home/dietpi/nlpservice/app/main.py:39]
2024-09-23 06:46:03,334 INFO: NLP Service startup [in /home/dietpi/nlpservice/app/main.py:39]
2024-09-23 06:46:03,334 INFO: NLP Service startup [in /home/dietpi/nlpservice/app/main.py:39]
2024-09-23 06:46:03,336 INFO: NLP Service startup [in /home/dietpi/nlpservice/app/main.py:60]
2024-09-23 06:46:03,336 INFO: NLP Service startup [in /home/dietpi/nlpservice/app/main.py:60]
2024-09-23 06:46:03,336 INFO: NLP Service startup [in /home/dietpi/nlpservice/app/main.py:60]
2024-09-23 06:46:03,336 INFO: NLP Service startup [in /home/dietpi/nlpservice/app/main.py:60]
2024-09-23 06:46:03,336 INFO: NLP Service startup [in /home/dietpi/nlpservice/app/main.py:60]
2024-09-23 06:46:03,336 INFO: NLP Service startup [in /home/dietpi/nlpservice/app/main.py:60]
2024-09-23 06:46:11,456 ERROR: Unhandled exception: name 'current_app' is not defined [in /home/dietpi/nlpservice/app/main.py:92]
2024-09-23 06:46:11,456 ERROR: Unhandled exception: name 'current_app' is not defined [in /home/dietpi/nlpservice/app/main.py:92]
2024-09-23 06:46:11,456 ERROR: Unhandled exception: name 'current_app' is not defined [in /home/dietpi/nlpservice/app/main.py:92]
2024-09-23 06:56:36,438 DEBUG: Logging configured [in /home/dietpi/nlpservice/app/main.py:38]
2024-09-23 06:56:36,438 DEBUG: Logging configured [in /home/dietpi/nlpservice/app/main.py:38]
2024-09-23 06:56:36,438 DEBUG: Logging configured [in /home/dietpi/nlpservice/app/main.py:38]
2024-09-23 06:56:36,438 DEBUG: Logging configured [in /home/dietpi/nlpservice/app/main.py:38]
2024-09-23 06:56:36,439 INFO: NLP Service startup [in /home/dietpi/nlpservice/app/main.py:39]
2024-09-23 06:56:36,439 INFO: NLP Service startup [in /home/dietpi/nlpservice/app/main.py:39]
2024-09-23 06:56:36,439 INFO: NLP Service startup [in /home/dietpi/nlpservice/app/main.py:39]
2024-09-23 06:56:36,439 INFO: NLP Service startup [in /home/dietpi/nlpservice/app/main.py:39]
2024-09-23 06:56:41,900 DEBUG: https://huggingface.co:443 "HEAD /nlptown/bert-base-multilingual-uncased-sentiment/resolve/main/config.json HTTP/11" 200 0 [in /home/dietpi/nlpservice/venv/lib/python3.11/site-packages/urllib3/connectionpool.py:546]
2024-09-23 06:56:41,902 DEBUG: https://huggingface.co:443 "HEAD /nlptown/bert-base-multilingual-uncased-sentiment/resolve/main/config.json HTTP/11" 200 0 [in /home/dietpi/nlpservice/venv/lib/python3.11/site-packages/urllib3/connectionpool.py:546]
2024-09-23 06:56:42,010 DEBUG: https://huggingface.co:443 "HEAD /nlptown/bert-base-multilingual-uncased-sentiment/resolve/main/model.safetensors HTTP/11" 404 0 [in /home/dietpi/nlpservice/venv/lib/python3.11/site-packages/urllib3/connectionpool.py:546]
2024-09-23 06:56:42,024 DEBUG: https://huggingface.co:443 "HEAD /nlptown/bert-base-multilingual-uncased-sentiment/resolve/main/model.safetensors HTTP/11" 404 0 [in /home/dietpi/nlpservice/venv/lib/python3.11/site-packages/urllib3/connectionpool.py:546]
2024-09-23 06:56:44,418 INFO: All resources loaded successfully [in /home/dietpi/nlpservice/app/nlp/analyzer.py:31]
2024-09-23 06:56:44,418 INFO: All resources loaded successfully [in /home/dietpi/nlpservice/app/nlp/analyzer.py:31]
2024-09-23 06:58:13,187 DEBUG: Logging configured [in /home/dietpi/nlpservice/app/main.py:40]
2024-09-23 06:58:13,187 DEBUG: Logging configured [in /home/dietpi/nlpservice/app/main.py:40]
2024-09-23 06:58:13,187 DEBUG: Logging configured [in /home/dietpi/nlpservice/app/main.py:40]
2024-09-23 06:58:13,187 DEBUG: Logging configured [in /home/dietpi/nlpservice/app/main.py:40]
2024-09-23 06:58:13,187 INFO: NLP Service startup [in /home/dietpi/nlpservice/app/main.py:41]
2024-09-23 06:58:13,187 INFO: NLP Service startup [in /home/dietpi/nlpservice/app/main.py:41]
2024-09-23 06:58:13,187 INFO: NLP Service startup [in /home/dietpi/nlpservice/app/main.py:41]
2024-09-23 06:58:13,187 INFO: NLP Service startup [in /home/dietpi/nlpservice/app/main.py:41]
2024-09-23 06:58:18,221 DEBUG: https://huggingface.co:443 "HEAD /nlptown/bert-base-multilingual-uncased-sentiment/resolve/main/config.json HTTP/11" 200 0 [in /home/dietpi/nlpservice/venv/lib/python3.11/site-packages/urllib3/connectionpool.py:546]
2024-09-23 06:58:18,224 DEBUG: https://huggingface.co:443 "HEAD /nlptown/bert-base-multilingual-uncased-sentiment/resolve/main/config.json HTTP/11" 200 0 [in /home/dietpi/nlpservice/venv/lib/python3.11/site-packages/urllib3/connectionpool.py:546]
2024-09-23 06:58:18,336 DEBUG: https://huggingface.co:443 "HEAD /nlptown/bert-base-multilingual-uncased-sentiment/resolve/main/model.safetensors HTTP/11" 404 0 [in /home/dietpi/nlpservice/venv/lib/python3.11/site-packages/urllib3/connectionpool.py:546]
2024-09-23 06:58:18,336 DEBUG: https://huggingface.co:443 "HEAD /nlptown/bert-base-multilingual-uncased-sentiment/resolve/main/model.safetensors HTTP/11" 404 0 [in /home/dietpi/nlpservice/venv/lib/python3.11/site-packages/urllib3/connectionpool.py:546]
2024-09-23 06:58:20,765 INFO: All resources loaded successfully [in /home/dietpi/nlpservice/app/nlp/analyzer.py:31]
2024-09-23 06:58:20,781 INFO: All resources loaded successfully [in /home/dietpi/nlpservice/app/nlp/analyzer.py:31]
2024-09-23 06:58:20,784 ERROR: Unhandled exception: 404 Not Found: The requested URL was not found on the server. If you entered the URL manually please check your spelling and try again. [in /home/dietpi/nlpservice/app/main.py:81]
Traceback (most recent call last):
  File "/home/dietpi/nlpservice/venv/lib/python3.11/site-packages/flask/app.py", line 880, in full_dispatch_request
    rv = self.dispatch_request()
         ^^^^^^^^^^^^^^^^^^^^^^^
  File "/home/dietpi/nlpservice/venv/lib/python3.11/site-packages/flask/app.py", line 854, in dispatch_request
    self.raise_routing_exception(req)
  File "/home/dietpi/nlpservice/venv/lib/python3.11/site-packages/flask/app.py", line 463, in raise_routing_exception
    raise request.routing_exception  # type: ignore[misc]
    ^^^^^^^^^^^^^^^^^^^^^^^^^^^^^^^
  File "/home/dietpi/nlpservice/venv/lib/python3.11/site-packages/flask/ctx.py", line 362, in match_request
    result = self.url_adapter.match(return_rule=True)  # type: ignore
             ^^^^^^^^^^^^^^^^^^^^^^^^^^^^^^^^^^^^^^^^
  File "/home/dietpi/nlpservice/venv/lib/python3.11/site-packages/werkzeug/routing/map.py", line 629, in match
    raise NotFound() from None
werkzeug.exceptions.NotFound: 404 Not Found: The requested URL was not found on the server. If you entered the URL manually please check your spelling and try again.
2024-09-23 06:58:20,784 ERROR: Unhandled exception: 404 Not Found: The requested URL was not found on the server. If you entered the URL manually please check your spelling and try again. [in /home/dietpi/nlpservice/app/main.py:81]
Traceback (most recent call last):
  File "/home/dietpi/nlpservice/venv/lib/python3.11/site-packages/flask/app.py", line 880, in full_dispatch_request
    rv = self.dispatch_request()
         ^^^^^^^^^^^^^^^^^^^^^^^
  File "/home/dietpi/nlpservice/venv/lib/python3.11/site-packages/flask/app.py", line 854, in dispatch_request
    self.raise_routing_exception(req)
  File "/home/dietpi/nlpservice/venv/lib/python3.11/site-packages/flask/app.py", line 463, in raise_routing_exception
    raise request.routing_exception  # type: ignore[misc]
    ^^^^^^^^^^^^^^^^^^^^^^^^^^^^^^^
  File "/home/dietpi/nlpservice/venv/lib/python3.11/site-packages/flask/ctx.py", line 362, in match_request
    result = self.url_adapter.match(return_rule=True)  # type: ignore
             ^^^^^^^^^^^^^^^^^^^^^^^^^^^^^^^^^^^^^^^^
  File "/home/dietpi/nlpservice/venv/lib/python3.11/site-packages/werkzeug/routing/map.py", line 629, in match
    raise NotFound() from None
werkzeug.exceptions.NotFound: 404 Not Found: The requested URL was not found on the server. If you entered the URL manually please check your spelling and try again.
2024-09-23 07:00:22,962 DEBUG: Received similarity calculation request [in /home/dietpi/nlpservice/app/api/routes.py:34]
