2024-09-23 07:00:22,962 DEBUG: Received similarity calculation request [in /home/dietpi/nlpservice/app/api/routes.py:34]
2024-09-23 07:00:22,962 ERROR: Error during similarity calculation: 'utf-8' codec can't decode byte 0xe9 in position 25: invalid continuation byte [in /home/dietpi/nlpservice/app/api/routes.py:47]
2024-09-23 07:00:22,962 ERROR: Error during similarity calculation: 'utf-8' codec can't decode byte 0xe9 in position 25: invalid continuation byte [in /home/dietpi/nlpservice/app/api/routes.py:47]
2024-09-23 07:00:26,377 DEBUG: Received analyze request [in /home/dietpi/nlpservice/app/api/routes.py:15]
2024-09-23 07:00:26,377 DEBUG: Received analyze request [in /home/dietpi/nlpservice/app/api/routes.py:15]
2024-09-23 07:00:26,377 DEBUG: Decoded text: Cet exemple de texte est en français.... [in /home/dietpi/nlpservice/app/api/routes.py:23]
2024-09-23 07:00:26,377 DEBUG: Decoded text: Cet exemple de texte est en français.... [in /home/dietpi/nlpservice/app/api/routes.py:23]
2024-09-23 07:00:26,377 DEBUG: Starting analysis of text: Cet exemple de texte est en français.... [in /home/dietpi/nlpservice/app/nlp/analyzer.py:38]
2024-09-23 07:00:27,092 INFO: Analysis completed successfully. [in /home/dietpi/nlpservice/app/nlp/analyzer.py:58]
2024-09-23 07:00:27,093 DEBUG: Analysis result: {'sentiment': '1 star', 'keyphrases': ['français', 'cet', 'exemple', 'texte'], 'category': 'Non catégorisé', 'named_entities': [], 'readability_score': 100, 'word_count': 8, 'sentence_count': 1, 'language': 'fr', 'lexical_diversity': 1.0, 'top_n_grams': [(('cet', 'exemple'), 1), (('exemple', 'de'), 1), (('de', 'texte'), 1), (('texte', 'est'), 1), (('est', 'en'), 1)], 'semantic_coherence': 1.0, 'sentiment_distribution': {'POSITIVE': 0.0, 'NEGATIVE': 0.0, 'NEUTRAL': 0.0}, 'average_sentence_length': 8.0} [in /home/dietpi/nlpservice/app/api/routes.py:25]
2024-09-23 07:00:27,093 DEBUG: Analysis result: {'sentiment': '1 star', 'keyphrases': ['français', 'cet', 'exemple', 'texte'], 'category': 'Non catégorisé', 'named_entities': [], 'readability_score': 100, 'word_count': 8, 'sentence_count': 1, 'language': 'fr', 'lexical_diversity': 1.0, 'top_n_grams': [(('cet', 'exemple'), 1), (('exemple', 'de'), 1), (('de', 'texte'), 1), (('texte', 'est'), 1), (('est', 'en'), 1)], 'semantic_coherence': 1.0, 'sentiment_distribution': {'POSITIVE': 0.0, 'NEGATIVE': 0.0, 'NEUTRAL': 0.0}, 'average_sentence_length': 8.0} [in /home/dietpi/nlpservice/app/api/routes.py:25]
2024-09-23 07:02:35,533 DEBUG: Logging configured [in /home/dietpi/nlpservice/app/main.py:40]
2024-09-23 07:02:35,533 DEBUG: Logging configured [in /home/dietpi/nlpservice/app/main.py:40]
2024-09-23 07:02:35,534 INFO: NLP Service startup [in /home/dietpi/nlpservice/app/main.py:41]
2024-09-23 07:02:35,534 INFO: NLP Service startup [in /home/dietpi/nlpservice/app/main.py:41]
2024-09-23 07:02:35,537 DEBUG: Logging configured [in /home/dietpi/nlpservice/app/main.py:40]
2024-09-23 07:02:35,537 DEBUG: Logging configured [in /home/dietpi/nlpservice/app/main.py:40]
2024-09-23 07:02:35,537 INFO: NLP Service startup [in /home/dietpi/nlpservice/app/main.py:41]
2024-09-23 07:02:35,537 INFO: NLP Service startup [in /home/dietpi/nlpservice/app/main.py:41]
2024-09-23 07:02:40,935 DEBUG: https://huggingface.co:443 "HEAD /nlptown/bert-base-multilingual-uncased-sentiment/resolve/main/config.json HTTP/11" 200 0 [in /home/dietpi/nlpservice/venv/lib/python3.11/site-packages/urllib3/connectionpool.py:546]
2024-09-23 07:02:41,005 DEBUG: https://huggingface.co:443 "HEAD /nlptown/bert-base-multilingual-uncased-sentiment/resolve/main/config.json HTTP/11" 200 0 [in /home/dietpi/nlpservice/venv/lib/python3.11/site-packages/urllib3/connectionpool.py:546]
2024-09-23 07:02:41,049 DEBUG: https://huggingface.co:443 "HEAD /nlptown/bert-base-multilingual-uncased-sentiment/resolve/main/model.safetensors HTTP/11" 404 0 [in /home/dietpi/nlpservice/venv/lib/python3.11/site-packages/urllib3/connectionpool.py:546]
2024-09-23 07:02:41,142 DEBUG: https://huggingface.co:443 "HEAD /nlptown/bert-base-multilingual-uncased-sentiment/resolve/main/model.safetensors HTTP/11" 404 0 [in /home/dietpi/nlpservice/venv/lib/python3.11/site-packages/urllib3/connectionpool.py:546]
2024-09-23 07:02:42,545 INFO: All resources loaded successfully [in /home/dietpi/nlpservice/app/nlp/analyzer.py:31]
2024-09-23 07:02:42,549 DEBUG: Received similarity calculation request [in /home/dietpi/nlpservice/app/api/routes.py:34]
2024-09-23 07:02:42,549 DEBUG: Received similarity calculation request [in /home/dietpi/nlpservice/app/api/routes.py:34]
2024-09-23 07:02:42,549 DEBUG: Decoded text1: Le chat est sur le tapis. [in /home/dietpi/nlpservice/app/api/routes.py:43]
2024-09-23 07:02:42,549 DEBUG: Decoded text1: Le chat est sur le tapis. [in /home/dietpi/nlpservice/app/api/routes.py:43]
2024-09-23 07:02:42,549 DEBUG: Decoded text2: Un chat dort sur le canap. [in /home/dietpi/nlpservice/app/api/routes.py:44]
2024-09-23 07:02:42,549 DEBUG: Decoded text2: Un chat dort sur le canap. [in /home/dietpi/nlpservice/app/api/routes.py:44]
2024-09-23 07:02:42,549 DEBUG: Starting similarity calculation [in /home/dietpi/nlpservice/app/nlp/analyzer.py:151]
2024-09-23 07:02:42,579 INFO: Similarity calculated: 0.4244295338926332 [in /home/dietpi/nlpservice/app/nlp/analyzer.py:156]
2024-09-23 07:02:42,579 DEBUG: Similarity result: {'similarity': 0.4244295338926332} [in /home/dietpi/nlpservice/app/api/routes.py:51]
2024-09-23 07:02:42,579 DEBUG: Similarity result: {'similarity': 0.4244295338926332} [in /home/dietpi/nlpservice/app/api/routes.py:51]
2024-09-23 07:02:42,579 INFO: All resources loaded successfully [in /home/dietpi/nlpservice/app/nlp/analyzer.py:31]
2024-09-23 07:02:42,582 ERROR: Unhandled exception: 404 Not Found: The requested URL was not found on the server. If you entered the URL manually please check your spelling and try again. [in /home/dietpi/nlpservice/app/main.py:81]
Traceback (most recent call last):
  File "/home/dietpi/nlpservice/venv/lib/python3.11/site-packages/flask/app.py", line 880, in full_dispatch_request
    rv = self.dispatch_request()
         ^^^^^^^^^^^^^^^^^^^^^^^
  File "/home/dietpi/nlpservice/venv/lib/python3.11/site-packages/flask/app.py", line 854, in dispatch_request
    self.raise_routing_exception(req)
  File "/home/dietpi/nlpservice/venv/lib/python3.11/site-packages/flask/app.py", line 463, in raise_routing_exception
    raise request.routing_exception  # type: ignore[misc]
    ^^^^^^^^^^^^^^^^^^^^^^^^^^^^^^^
  File "/home/dietpi/nlpservice/venv/lib/python3.11/site-packages/flask/ctx.py", line 362, in match_request
    result = self.url_adapter.match(return_rule=True)  # type: ignore
             ^^^^^^^^^^^^^^^^^^^^^^^^^^^^^^^^^^^^^^^^
  File "/home/dietpi/nlpservice/venv/lib/python3.11/site-packages/werkzeug/routing/map.py", line 629, in match
    raise NotFound() from None
werkzeug.exceptions.NotFound: 404 Not Found: The requested URL was not found on the server. If you entered the URL manually please check your spelling and try again.
2024-09-23 07:02:42,582 ERROR: Unhandled exception: 404 Not Found: The requested URL was not found on the server. If you entered the URL manually please check your spelling and try again. [in /home/dietpi/nlpservice/app/main.py:81]
Traceback (most recent call last):
  File "/home/dietpi/nlpservice/venv/lib/python3.11/site-packages/flask/app.py", line 880, in full_dispatch_request
    rv = self.dispatch_request()
         ^^^^^^^^^^^^^^^^^^^^^^^
  File "/home/dietpi/nlpservice/venv/lib/python3.11/site-packages/flask/app.py", line 854, in dispatch_request
    self.raise_routing_exception(req)
  File "/home/dietpi/nlpservice/venv/lib/python3.11/site-packages/flask/app.py", line 463, in raise_routing_exception
    raise request.routing_exception  # type: ignore[misc]
    ^^^^^^^^^^^^^^^^^^^^^^^^^^^^^^^
  File "/home/dietpi/nlpservice/venv/lib/python3.11/site-packages/flask/ctx.py", line 362, in match_request
    result = self.url_adapter.match(return_rule=True)  # type: ignore
             ^^^^^^^^^^^^^^^^^^^^^^^^^^^^^^^^^^^^^^^^
  File "/home/dietpi/nlpservice/venv/lib/python3.11/site-packages/werkzeug/routing/map.py", line 629, in match
    raise NotFound() from None
werkzeug.exceptions.NotFound: 404 Not Found: The requested URL was not found on the server. If you entered the URL manually please check your spelling and try again.
2024-09-23 07:02:42,661 ERROR: Unhandled exception: 404 Not Found: The requested URL was not found on the server. If you entered the URL manually please check your spelling and try again. [in /home/dietpi/nlpservice/app/main.py:81]
Traceback (most recent call last):
  File "/home/dietpi/nlpservice/venv/lib/python3.11/site-packages/flask/app.py", line 880, in full_dispatch_request
    rv = self.dispatch_request()
         ^^^^^^^^^^^^^^^^^^^^^^^
  File "/home/dietpi/nlpservice/venv/lib/python3.11/site-packages/flask/app.py", line 854, in dispatch_request
    self.raise_routing_exception(req)
  File "/home/dietpi/nlpservice/venv/lib/python3.11/site-packages/flask/app.py", line 463, in raise_routing_exception
    raise request.routing_exception  # type: ignore[misc]
    ^^^^^^^^^^^^^^^^^^^^^^^^^^^^^^^
  File "/home/dietpi/nlpservice/venv/lib/python3.11/site-packages/flask/ctx.py", line 362, in match_request
    result = self.url_adapter.match(return_rule=True)  # type: ignore
             ^^^^^^^^^^^^^^^^^^^^^^^^^^^^^^^^^^^^^^^^
  File "/home/dietpi/nlpservice/venv/lib/python3.11/site-packages/werkzeug/routing/map.py", line 629, in match
    raise NotFound() from None
werkzeug.exceptions.NotFound: 404 Not Found: The requested URL was not found on the server. If you entered the URL manually please check your spelling and try again.
